Workbook

Sheet Visitestage
A1: Timestamp | B1: Email Address | C1: Untitled Question | D1: Nombre visiteurs/stagiaires | E1: Objet | F1: Site concerné/Secteur Nord | G1: Site concerné/ Secteur Centre | H1: Site concerné/ Secteur Sud | I1: Lieu de provenance | J1: Organisation /Institution de provenance | K1: Motif | L1: Column 11 | M1: Date d'arrivée | N1: Date de départ | O1: Heure d'arrivé | P1: Heure de départ | Q1: Observation | R1: Annexe ( Liste de présence, Photo, etc.) | S1: Description
A2: 45959.678 | B2: bbwende@virunga.org | D2: 3 | E2: Visite | F2: Mutsora | G2: RAS | H2: RAS | I2: Beni | J2: Espace | M2: 45958 | N2: 45959 | O2: 0 | P2: 0.54166667 | Q2: Satisfaction | R2: https://drive.google.com/open?id=1AVSwrBUB6GiHz3DRRPzGMm1pb-VjnhTU
A3: 45959.68 | B3: bbwende@virunga.org | D3: 3 | E3: Visite | F3: Mutsora | G3: RAS | H3: RAS | I3: Beni | J3: Espace | M3: 45958 | N3: 45959 | O3: 0 | P3: 0.45833333 | Q3: Satisfaction | R3: https://drive.google.com/open?id=1R72ufkbCbOPpLwyG_sGzuHrpNeLKlO7m
A4: 45967.598 | B4: gregoirekambis@gmail.com | D4: 22 | E4: Stage | F4: Mutsora | G4: RAS | H4: RAS | I4: Goma, Butembo | J4: UNIGOMA, UCG ET ISEAVF | M4: 45950 | N4: 45963 | O4: 0.42430556 | P4: 0.3125 | Q4: Ras | R4: https://drive.google.com/open?id=1DU5cGSefYC3UJxA-EHQ0Uqd1ZvxkcWq_
A5: 45972.488 | B5: jkalala@virunga.org | D5: 39 | E5: Recherche | F5: Espace Virunga Beni | G5: RAS | H5: RAS | I5: Multiple | J5: Multiple | M5: 45938 | N5: 45938 | O5: 0.33333333 | P5: 0.70833333 | Q5: La bibliothèque et l'espace de travail de Virunga offre un cadre aux riverains pour s'émouvoir ; nombreux y passent leur temps pour la lecture des livres , la recherche sur internet, postulent aux offres d'emplois, font de TP, des mémoires, TFC etc | R5: https://drive.google.com/open?id=1uZIUPFlrxTE9DU4mWzAdt-WFFSfVtTnN
A6: 45972.496 | B6: jkalala@virunga.org | D6: 14 | E6: Recherche | F6: Espace Virunga Beni | G6: RAS | H6: RAS | I6: Multiple | J6: Multiple | M6: 45960 | N6: 45960 | O6: 0.33333333 | P6: 0.70833333 | Q6: La bibliothèque et l'espace de travail de Virunga offre un cadre aux riverains pour s'émouvoir ; nombreux y passent leur temps pour la lecture des livres , la recherche sur internet, postulent aux offres d'emplois, font de TP, des mémoires, TFC etc | R6: https://drive.google.com/open?id=1RtN7BbabBjB5Tp7nAzjE_Z3Lw4xVydjf
A7: 45972.497 | B7: jkalala@virunga.org | D7: 23 | E7: Recherche | F7: RAS | G7: RAS | H7: RAS | I7: Multiple | J7: Multiple | M7: 45953 | N7: 45953 | O7: 0.375 | P7: 0.72916667 | Q7: La bibliothèque et l'espace de travail de Virunga offre un cadre aux riverains pour s'émouvoir ; nombreux y passent leur temps pour la lecture des livres , la recherche sur internet, postulent aux offres d'emplois, font de TP, des mémoires, TFC etc | R7: https://drive.google.com/open?id=1Z8rYNHqyXf3KaDQxirXEOS2koFTrAt_V
A8: 45972.499 | B8: jkalala@virunga.org | D8: 21 | E8: Recherche | F8: Espace Virunga Beni | G8: RAS | H8: RAS | I8: Multiple | J8: Multiple | M8: 45931 | N8: 45931 | O8: 0.70833333 | P8: 0.375 | Q8: La bibliothèque et l'espace de travail de Virunga offre un cadre aux riverains pour s'émouvoir ; nombreux y passent leur temps pour la lecture des livres , la recherche sur internet, postulent aux offres d'emplois, font de TP, des mémoires, TFC etc | R8: https://drive.google.com/open?id=1DQQmgEcB_168st24EUAoavfklS9X0XXX
A9: 45972.503 | B9: jkalala@virunga.org | D9: 26 | E9: Recherche | F9: Espace Virunga Beni | G9: RAS | H9: RAS | I9: Multiple | J9: Multiple | M9: 45953 | N9: 45953 | O9: 0.70833333 | P9: 0.375 | Q9: La bibliothèque et l'espace de travail de Virunga offre un cadre aux riverains pour s'émouvoir ; nombreux y passent leur temps pour la lecture des livres , la recherche sur internet, postulent aux offres d'emplois, font de TP, des mémoires, TFC etc | R9: https://drive.google.com/open?id=1qe7SvylVqc0vXl0H_WjyViPU13VklUn6
A10: 45972.505 | B10: jkalala@virunga.org | D10: 22 | E10: Recherche | F10: Espace Virunga Beni | G10: RAS | H10: RAS | I10: Multiple | J10: Multiple | M10: 45952 | N10: 45952 | O10: 0.70833333 | P10: 0.375 | Q10: La bibliothèque et l'espace de travail de Virunga offre un cadre aux riverains pour s'émouvoir ; nombreux y passent leur temps pour la lecture des livres , la recherche sur internet, postulent aux offres d'emplois, font de TP, des mémoires, TFC etc | R10: https://drive.google.com/open?id=106gmBhS6D04zgEzzWQU4uWW8QkBjQppg
A11: 45972.52 | B11: jkalala@virunga.org | D11: 20 | E11: Recherche | F11: Espace Virunga Beni | G11: RAS | H11: RAS | I11: Multiple | J11: Multiple | M11: 45933 | N11: 45933 | O11: 0.375 | P11: 0.70833333 | Q11: La bibliothèque et l'espace de travail de Virunga offre un cadre aux riverains pour s'émouvoir ; nombreux y passent leur temps pour la lecture des livres , la recherche sur internet, postulent aux offres d'emplois, font de TP, des mémoires, TFC etc | R11: https://drive.google.com/open?id=1VaGJYphUaO8XyQ5CuRyzOX6Ng7d23HOL
A12: 45972.522 | B12: jkalala@virunga.org | D12: 20 | E12: Recherche | F12: Espace Virunga Beni | G12: RAS | H12: RAS | I12: Multiple | J12: Multiple | M12: 45936 | N12: 45936 | O12: 0.375 | P12: 0.70833333 | Q12: La bibliothèque et l'espace de travail de Virunga offre un cadre aux riverains pour s'émouvoir ; nombreux y passent leur temps pour la lecture des livres , la recherche sur internet, postulent aux offres d'emplois, font de TP, des mémoires, TFC etc | R12: https://drive.google.com/open?id=1NSkutxzwEvti96tPt-CJgwhWLAg1dBwm
A13: 45972.529 | B13: jkalala@virunga.org | D13: 121 | E13: Visite | F13: Espace Virunga Beni | G13: RAS | H13: RAS | I13: École Marie Correnson | J13: ÉCOLE MARIE CORRENSON | M13: 45959 | N13: 45959 | O13: 0.375 | P13: 0.625 | Q13: L'école est venue découvrir les avantages qu'offre le PNVI notamment la bibliothèque gratuite. Elle a aussi bénéficié d'un partage sur l'importance du PNVI dans notre région ; Enthousiasmé par ces avantages, les élèves ont commencé à passer à la bibliothèque pour la lecture ! | R13: https://drive.google.com/open?id=1FRr3-a1eY1d3fqh48a1h1jhYJ54zuCaY, https://drive.google.com/open?id=1IaSFTcCFMbXynGz2UjlygdPQ9FanD0dz, https://drive.google.com/open?id=1hf1iQdrBrJs6AS47TvIwUPUmZAXNuJJZ
A14: 45973.389 | B14: bbwende@virunga.org | D14: 34 | E14: Stage | F14: Mutsora | G14: RAS | H14: RAS | I14: Goma | J14: Isdr | M14: 45950 | N14: 45976 | O14: 0 | P14: 0.54166667 | Q14: Visite satisfaisante | R14: https://drive.google.com/open?id=1XB_yCqzP731im52Z_fIGbrVn8lkPIlm0
A15: 45980.739 | B15: jkalala@virunga.org | D15: RECHERCHE | E15: Recherche | F15: Espace Virunga Beni | G15: RAS | H15: RAS | I15: Multiple | J15: Multiple | M15: 45980 | N15: 45980 | O15: 0.375 | P15: 0.70833333 | Q15: Les visites ce dernier temps sont intenses et nombreux se concentrent énormément au travail que les fois passées! | R15: https://drive.google.com/open?id=1zDB74MWZtglRr-nfQa7T4thrcEqA-5oq
A16: 45983.424 | B16: jkalala@virunga.org | D16: 34 | E16: Recherche | F16: Espace Virunga Beni | G16: RAS | H16: RAS | I16: Multiple | J16: Multiple | M16: 45980 | N16: 45982 | O16: 0.375 | P16: 0.70833333 | Q16: Durant une période de 4 jours ,nous avons reçu une trentaine de visite à l'espace Virunga origins du côté bibliothèque et salle de travail | R16: https://drive.google.com/open?id=1fl4iGePg92sSiVReCT9ZJ_oWjGC83t34

Sheet Donnees_Activites
A1: Timestamp | B1: Email Address | C1: Nom de l'activité | D1: Organisateur | E1: Type d'activité | F1: Description de l'activité | G1: Date de l'activité | H1: Durée de l'activité | I1: Lieu de l'activité ( Secteur) | J1: Préciser le lieu | K1: Nombre de participants - Hommes | L1: Nombre de participants - Femmes | M1: Nombre de participants - Enfants | N1: Acquis et résultats de l'activité | O1: Pièce jointe | P1: Membres de l'équipe | Q1: Messages Clés | R1: Fait marquant | S1: Suggestions et recommandations clés
A2: 45961.546 | B2: jisango@virunga.org | C2: Cérémonie officielle | D2: Ville de Goma | E2: Cérémonie officielle | F2: La cérémonie officielle journée de l’arbre | G2: 45954 | H2: 1 h - 2 h | I2: Sud | J2: Goma | K2: 29 | L2: 14 | M2: 6 | N2: Journée de Nation Unies | P2: 1
A3: 45961.585 | B3: jisango@virunga.org | C3: Séance éducative et CoCo / Secteur Centre | D3: Parc National des Virunga | E3: Sensibilisation | F3: Educ Envir & COCO : les leaders communautaires de Nyamilima et Ishasha ont été sensibilisés sur la nécessité et le rôle qu’ils sont appelés à jouer dans la préservation des écosystèmes et la sauvegarde du PNVi. A l’issue de ces séances, ces représentants de différentes couches de la population dont les cadres de base ont accepté de s’impliquer activement dans la protection du PNVi et de s’approprier l’ensemble du programme Alliance Virunga. A Nyamilima par exemple, ils ont pris l’engagement de collaborer avec le parc en sensibilisant à leur tour pour décourager toutes les activités incompatibles avec la conservation, de participer à la protection de la clôture électrique et les équipements du projet de l’électricité. Plusieurs recommandations ont été formulées pour consolider cette stratégie de communication de proximité. | G3: 45952 | H3: 1 h - 2 h | I3: Centre | J3: Nyamilima | K3: 32 | L3: 14 | M3: 21 | N3: NYAMILIMA 67 leaders communautaires dont les cadres de base, les représentants des associations féminines, de la jeunesse, des petits commerces et agriculteurs ont été informés sur les défis de la conservation au PNVi spécialement dans le gpment Binza. Les participants se sont engagés à jouer un rôle primordial dans la sensibilisation des riverains en faveur de la préservation des valeurs écologiques du PNVi ; Les participants se sont engagés à sensibiliser contre les menaces et les conséquences des activités incompatibles avec la conservation dans le secteur centre du PNVi ; Les participants et l’équipe EE & COCO Centre ont pris l’engagement de multiplier ces genres de séances pour renforcer la communication de proximité afin d’améliorer le climat de collaboration avec les populations riveraines en vue d’une bonne conservation communautaire. | O3: https://drive.google.com/open?id=1ESNufVdmGDyP4nOurEhz0wbaTtIB363A | P3: Olivier Mukisya, JB Bichamakara , Katya Katondolo, Joelle Isango
A4: 45961.591 | B4: jisango@virunga.org | C4: Séance éducative et CoCo/ Secteur Centre | D4: Parc National des Virunga | E4: Sensibilisation | F4: Educ Envir & COCO : les leaders communautaires d’ Ishasha ont été sensibilisés sur la nécessité et le rôle qu’ils sont appelés à jouer dans la préservation des écosystèmes et la sauvegarde du PNVi. A l’issue de ces séances, ces représentants de différentes couches de la population dont les cadres de base ont accepté de s’impliquer activement dans la protection du PNVi et de s’approprier l’ensemble du programme Alliance Virunga. | G4: 45953 | H4: 1 h - 2 h | I4: Centre | J4: Ishasha | K4: 51 | L4: 19 | M4: 12 | N4: ISHASHA 82 leaders communautaires dont les cadres de base, les représentants des associations féminines, de la jeunesse, des petits commerces et agriculteurs ont été informés sur les défis de la conservation au PNVi spécialement dans le gpment Binza. Les participants se sont engagés à jouer un rôle primordial dans la sensibilisation des riverains en faveur de la préservation des valeurs écologiques du PNVi ; Les participants se sont engagés à sensibiliser contre les menaces et les conséquences des activités incompatibles avec la conservation dans le secteur centre du PNVi ; Les participants et l’équipe EE & COCO Centre ont pris l’engagement de multiplier ces genres de séances pour renforcer la communication de proximité afin d’améliorer le climat de collaboration avec les populations riveraines en vue d’une bonne conservation communautaire. | O4: https://drive.google.com/open?id=1o01QR96INcPY0ueOKrHqJJ3jG37AJjeY | P4: Olivier Mukisya, Joelle Isango, Katya Katondolo, JB Bichamakara
A5: 45961.682 | B5: bbwende@virunga.org | C5: Conservation durable du PNVi, Cohabitation pacifique, dévéloppement des rivérains | D5: Kwetu Nature | E5: Conférence | F5: Cette activité organisé par Kwetu Nature s’incrit dans la sensibilisation des riverains du parc pour la sauvegarde de ce patrimoine. Elle est la suite des actions de sensibilisation lancées depuis le centenaire du PNVi. Les jeunes sont les plus représentés dans l’activité | G5: 45961 | H5: 2 h - 3 h | I5: Nord | J5: Kyavinyonge | K5: 55 | L5: 15 | M5: 0 | N5: Renforcement des liens avec la population de Kyavinyonge en cette periode où le parc est victime des campagnes de bashing, Lever des zones d'ombres sur les actions du PNVi, | O5: https://drive.google.com/open?id=1Oqu5lUgxksMsow2Dz7jS6w234MjTHTR4 | P5: Kitakya Eric, Landry, Bienvenu Bwende, Bikanza, Gregoire Banyanito | Q5: - Le secteur Nord du PNVi regorge de richesses en biodiversité - La conservation du Parc est plus bénéfique que la destruction de la biodiversité - La cohabitation pacifique entre le Parc et les riverains contribue à l'apaisement et au développement notamment dans les pêcheries - Le PNVi est permis les principaux pourvoyeurs d'emploi dans la province grâce à l'AV - Le lac eduard est une ressources importantes si bien geré | R5: Participation du chef de village, des présidents de la Sociv, de la jeunesse et des associations feminines | S5: Formation des "reservistes" Ecogardes parmis les jeunes de Kyavinyonge
A6: 45964.569 | B6: bbwende@virunga.org | C6: Lancement de la construction du FOB MBAU | D6: Parc National des Virunga | E6: Cérémonie officielle | F6: Le lancement des travaux a été marqué par un salongo communautaire spécial ayant mobilisé massivement la population de Mbau et d’Oicha pour la préparation du site qui abritera les futures infrastructures du FOB.Cette activité s’inscrit dans le cadre du projet du Couloir Vert Kivu–Kinshasa, une initiative qui vise à combiner sécurité, développement communautaire et conservation. | G6: 45936 | H6: Plus de 6 h | I6: Nord | J6: Kelekele/Mbau | K6: 1500 | L6: 10 | M6: 0 | N6: Adhésion communautaire et appropriation du projet par les communautés locales, visibilité accrue de l’ICCN et L’UE, Consolidation des relations entre ICCN et les communautés | O6: https://drive.google.com/open?id=1HTtasZAW3XLCmeK5_HLJozrqX9YdbbaE | P6: Jérôme Lombard, Fabien Olengabo, Bienvenu BWENDE, JC Bambanze, Merdi Baraka, Conservateur Fils | Q6: Le FOB est un dispositif qui allie sécurité, développement et formation des jeunes; Il va couvrir Mbau, Oicha et les environs; c’est une opportunité d'emploi pour les jeunes; Nécessité d'appropriation du projet par les populations locales | R6: Forte mobilisation, présence des chefs locaux et cadres de base, quasiment toute la surface du site du projet défricher | S6: Indemnisation des cultures détruites, favoriser les jeunes locaux pour les emplois
A7: 45964.58 | B7: bbwende@virunga.org | C7: Remise de la ration à la prison de Kangbayi | D7: Parc National des Virunga | E7: Appui humanitaire | F7: À la suite des recommandations formulées lors de l’atelier du 27 novembre 2024 sur la problématique des décès à la prison urbaine de Beni, organisé par l’Unité d’Appui à l’Administration Pénitentiaire en collaboration avec la Section d’Appui à la Justice et présidé par le Maire de la ville de Beni, plusieurs institutions et partenaires ont été appelés à contribuer à l’amélioration des conditions carcérales des détenus de la Prison Centrale de Kangbayi. C’est dans ce contexte que l’ICCN, à travers le Parc National des Virunga (PNVi), a organisé la présente mission humanitaire de remise d’un lot de vivres destinés à la ration alimentaire des détenus de la Prison Centrale de Kangbayi. | G7: 45940 | H7: 1 h - 2 h | I7: Nord | J7: Kangbayi/Beni | K7: 10 | L7: 0 | M7: 0 | N7: Forte reconnaissance des gestionnaire de la prison; Geste salué par les communautés dans un moment de tension alimentés par les rumeurs ; | O7: https://drive.google.com/open?id=1UHcALjnjbQAOtRT91C_TzlJM5n5J0eQw | P7: Kitakya Eric, Bienvenu BWENDE, Paluku Bikanza, Kaley Grace | Q7: L’ICCN reste aux côtés des vulnérables; | R7: Visite des prisonnier | S7: Poursuivre la dynamique régulièrement
A8: 45964.594 | B8: jkalala@virunga.org | C8: 7 ARTS PLUS du 2 Fevrier 2025 | D8: Parc National des Virunga | E8: Activité Culturelle | F8: 7 arts Plus est une activité culturelle de promotion des artistes locaux émergents, elle est une activité hebdomadaire organisée chaque jeudi à l'Espace Virunga Origins par le PNVI et 4 groupes culturels des jeunes de BENI ville | G8: 45932 | H8: 3 h - 4 h | I8: Nord | J8: ESPACE VIRUNGA ORIGINS | K8: 8O | L8: 30 | M8: 0 | N8: De jeunes issu des différents coins de la ville de Beni se ruent à l'espace virunga chaque jeudi pour évoluer avec leur talent | O8: https://drive.google.com/open?id=1s9lV9frRxIH0MJ__aY3hkgNLI-kJF71i | P8: Jeff SUDI | Q8: Promotion de la Culture et de l'Art | R8: Le territoire de Beni et la ville de Butembo commence aussi à venir à l'espace virunga pour saisir l'opportunité de se faire vilgarisé à travers 7 arts plus | S8: l'activité souffre en ce jour de manque de moyen pour son ascension, notamment les instruments sonores, des instruments de musique et des visibilités imprimées
A9: 45964.621 | B9: jkalala@virunga.org | C9: 7 ARTS PLUS | D9: Parc National des Virunga | E9: ACTIVITE CULTURELLE | F9: 7 arts Plus est une activité culturelle de promotion des artistes locaux émergents, elle est une activité hebdomadaire organisée chaque jeudi à l'Espace Virunga Origins par le PNVI et 4 groupes culturels des jeunes de BENI ville | G9: 45939 | H9: 3 h - 4 h | I9: Nord | J9: Espace Virunga Origins | K9: 60 | L9: 10 | M9: 0 | N9: L'ACTIVITE A REUNI ENVIRON 20 GUITARISTES DE LA VILLE QUI ONT PASSE UN MESSAGE D'UNION DANS L'ART A BENI | O9: https://drive.google.com/open?id=1L_5tXXT2Aej0sEOPicR9qXqGpclVneSO | P9: JEFF SUDI | Q9: PROMOTION LES ARTS LOCAUX COMME JAMAIS AUPARAVANT: LA GUITARE AU SERVICE DE L ART LOCAL | R9: UNE FILLE GUITARISTE ISSUE DE L'EGLISE ARCHE A ÉBLOUI TOUT LE MONDE AVEC SA MAÎTRISE DE L'INSTRUMENT | S9: RAS
A10: 45964.624 | B10: jkalala@virunga.org | C10: 7 Arts Plus | D10: Parc National des Virunga | E10: Activité Culturelle | F10: 7 arts Plus est une activité culturelle de promotion des artistes locaux émergents, elle est une activité hebdomadaire organisée chaque jeudi à l'Espace Virunga Origins par le PNVI et 4 groupes culturels des jeunes de BENI ville | G10: 45946 | H10: 3 h - 4 h | I10: Nord | J10: ESPACE VIRUNGA ORIGINS | K10: 70 | L10: 15 | M10: 0 | N10: Réussite de l'activité malgré les difficultés car les jeunes restent résistant | P10: Jeff SUDI | Q10: Promotion d'artistes émergents | R10: RAS | S10: RAS
A11: 45964.63 | B11: jkalala@virunga.org | C11: 7 ARTS PLUS | D11: Parc National des Virunga | E11: Activité Culturelle | F11: 7 arts Plus est une activité culturelle de promotion des artistes locaux émergents, elle est une activité hebdomadaire organisée chaque jeudi à l'Espace Virunga Origins par le PNVI et 4 groupes culturels des jeunes de BENI ville | G11: 45953 | H11: 3 h - 4 h | I11: Nord | J11: ESPACE VIRUNGA ORIGINS | K11: 100 | L11: 10 | M11: 0 | N11: Production de 11 arts émergents de la ville de BENI dont 3 filles et 8 garçons | O11: https://drive.google.com/open?id=1OBUinkp4FL1WH9Dah0MBy9pMfXkintjx | P11: JEFF SUDI | Q11: L'arts pour tous , | R11: Un artiste de Ngadi a tiré l'attention de tous par sa présence et son dévouement à l'art | S11: DOTATION DE MOYEN ADÉQUAT POUR L'AMÉLIORATION DES CONDITIONS DE L'ACTIVITÉ QUI PORTE L'ACTIVITÉ DANS LE MILIEU DE JEUNE DE LA RÉGION
A12: 45964.906 | B12: jkalala@virunga.org | C12: Visite de l'Espace VIRUNGA | D12: Marie Correnson | E12: Visite Guidée | F12: La Visite Guidée est une activité qui permet aux écoles de découvrir le PNVI à travers l'espace VIRUNGA, les responsables d'école en collaboration avec l'assistant EE Secteur Nord s'attendent sur une date pour faire découvrir, la bibliothèque, l'espace de travail, la salle polyvalente, l'espace Virunga, les activités du PNVI son importance, les agents qui le protègent et leur rôle etc. | G12: 45959 | H12: 5 h - 6 h | I12: Nord | J12: Espace Virunga | K12: 67 | L12: 54 | M12: 119 | N12: Depuis la visite, les élèves de l'école arrivent régulièrement à la bibliothèque | O12: https://drive.google.com/open?id=10lijW3IYcU73Z7yfvP5yk1DMQrxoBgIK | P12: Jeff SUDI | Q12: Importance de la bibliothèque aux élèves et la nécessité de protéger un parc | R12: RAS | S12: Il faut ajouter les documentaires sur le PNVI
A13: 45967.425 | B13: bbwende@virunga.org | C13: Restitution et validation de résultats du rapport technique de la commission sur le limites du PNVi dans le Beni | D13: Parc National des Virunga | E13: Atelier | F13: Cet atelier vise à présenter le rapport technique des experts aux reste des membres de la commission afin que ces dernier en prennent connaissance et le valide. Une fois validé ce rapport va être soumis au gouverneur de province qui prévoit de convoquer un atelier élargie pour les présenter et proposer des solutions pour régler le conflit des limites du PNVi dans le territoire de Beni | G13: 45965 | H13: 5 h - 6 h | I13: Nord | J13: Beni ville | K13: 18 | L13: 2 | M13: 0 | N13: Rapport présenté à la commission ; recommandations récoltées et seront intégré dans le rapport; La commission contente du travail effectuée par les experts | O13: https://drive.google.com/open?id=1zHqJ4qQbd2VoKVAB_tOfImZTz3AKloW4 | P13: Méthode Uhoze; Bienvenu BWENDE | Q13: Presentation des résultats segment par segment et carte à l’appui; La commission doit prendre conscience de la responsabilité qui lui incombe pour la résolution; Ce rapport va permettre à l’autorité et aux autres acteurs de prendre des décisions pour résoudre les différents conflits | R13: Débats parfois houleux notamment sur Mayangose; réunion prolongé sur 2 jours au lieu d'un jour prévu à l'avance; prochaine rencontre prévue le samedi 8/11 | S13: Prendre en compte les points présentés par les communautés sur terrain dans le rapport ; Souligné les lacunes contenus dans la loi de delimitant le parc
A14: 45972.31 | B14: bbwende@virunga.org | C14: Atelier de validation du rapport technique de la commission de clarification des limites du PNVi (suite) | D14: Parc National des Virunga | E14: Atelier | F14: Suite de la présentation du rapport par les experts et intégration des recommandations formulés lors de la réunion du lundi à Mardi | G14: 45969 | H14: 4 h - 5 h | I14: Nord | J14: Beni ville | K14: 8 | L14: 2 | M14: 0 | N14: Rapprochement des positions des membres de la commission ; ramassage de plus de recommandations ; Éclairci sur le rapport final | O14: https://drive.google.com/open?id=1ASOPZslHFcNvTJobdjY7pIZCjA8MikE- | P14: Methode Uhoze; Bienvenu BWENDE | Q14: Finalisation du rapport et transmission prochaine au president de la commission puis au Gouverneur; les prochaines actions seront communiquées par le président de la commission | R14: Faible participation des membres de la commission;
A15: 45980.435 | B15: jkalala@virunga.org | C15: Visite Bibliothèque et Recherche | D15: Collectif BEN'ART | E15: Concours | F15: Le concours de génies en herbe est une activité organisée par le collectif BEN'ART pendant deux jours pour tester le niveau d'implication des écoles vis à vis du PNVI après un long moment de silence ! Cette activité a mis en compétition 5 écoles de la ville sur les matières suivantes : code de famille, PNVI , culture générale, epellation, cantonade, lecture et dictée. | G15: 45973 | H15: Plus de 6 h | I15: Nord | J15: ESPACE VIRUNGA ORIGINS | K15: 6 | L15: 2 | M15: 300 | N15: Une participation massive des élèves et une promesse d'être toujours prêt à participer aux activités du PNVI et des ces partenaires | O15: https://drive.google.com/open?id=1_En-7ajrVE4V_FvdcY3o8Zk2auDoOYsR | P15: JEFF SUDI | Q15: Connaitre ces droits et devoirs pour mieux protéger le PNVI | R15: RAS | S15: Le PNVI devrait organiser régulièrement ces genres d'activités ou encourager ces partenaires de le faire , d'abord dans tout le secteur Nord et couronner les meilleurs par une visite dans le PNVI
A16: 45980.455 | B16: jkalala@virunga.org | C16: Finale Génies en Herbe | D16: Collectif BEN'ART | E16: Concours | F16: Le concours de génies en herbe est une activité organisée par le collectif BEN'ART pendant deux jours pour tester le niveau d'implication des écoles vis à vis du PNVI après un long moment de silence ! Cette activité a mis en compétition 5 écoles de la ville sur les matières suivantes : code de famille, PNVI , culture générale, epellation, cantonade, lecture et dictée. | G16: 45975 | H16: Plus de 6 h | I16: Nord | J16: Espace Virunga origins | K16: 10 | L16: 2 | M16: 400 | N16: Engagement des écoles aux luttes du PNVI et de ces partenaires | O16: https://drive.google.com/open?id=1P3DctiT6Zk8NlG-Fxri0t2T8LHm99Pfu | P16: JEFF SUDI | Q16: Connaitre ces droits et devoirs pour mieux protéger le PNVI | R16: RAS | S16: Que le PNVI s'engage activement dans les genres d'événements
A17: 45983.565 | B17: jisango@virunga.org | C17: Réunion préparatifs | D17: Parc National des Virunga | E17: Réunion | F17: Reunion préparatifs avec les autorités de la pêcherie, les Directeur, les comptable….. | G17: 45979 | H17: Moins d' 1h | I17: Centre | J17: Nyakakoma | K17: 8 | L17: 2 | M17: 0 | N17: Une vision commune a été rétablie entre la pêcherie…. et le parc pour préparer efficacement la journée du 20 nov | O17: https://drive.google.com/open?id=1n8ozAqRMJbiUDRJ-KnzvBEVHN8ypH2sh | P17: Five Grégoire , Five Martin , Coco Jean Bosco BICHAMAKARA, Joelle Isango, | Q17: Renforcer notre coordination pour une gestion responsable et harmonieuse de la pêcherie à Nyakakoma | R17: La bonne ambiance, l’ambiance de paix | S17: La bonne déroulement de l’activité du 20
A18: 45983.585 | B18: jisango@virunga.org | C18: Séance éducative entre L’ICCN et la communauté de Nyakakoma | D18: Parc National des Virunga | E18: Sensibilisation | F18: Cette activité est une séance éducative entre L’ICCN et la communauté de Nyakakoma pour renforcer la compréhension et la collaboration dans la protection du Parc. Elle vise à sensibiliser la population sur les défis du parc, la clôture électrique et les projets communautaires comme forage et le biogaz | G18: 45981 | H18: 1 h - 2 h | I18: Centre | J18: Nyakakoma | K18: 78 | L18: 14 | M18: 5 | N18: Meilleure compréhension du rôle de L’ICCN renforcement de la collaboration avec la communauté, sensibilisation réussie sur la clôture électrique et les projets de forage et biogaz | O18: https://drive.google.com/open?id=1LKQhb-57-5kfbZWdAju8LwKwjG6i9KIx | P18: JEAN BOSCO BICHAMAKARA, Olivier Mukisya, Joelle Isango , Katya Emmanuel | Q18: Protéger virunga est notre responsabilité commune, ensemble, Communauté et ICCN nous assurons la sécurité et l’avenir de Nyakakoma | R18: Participation active et engagement renforcé pour protéger Virunga | S18: Renforcer la gestion participative en impliquant d’avantage la communauté dans les projets du Parc. Encourager les respect des règles, la protection de la nature et la collaboration continue avec L’ICCN
A19: 45983.623 | B19: jisango@virunga.org | C19: Notre arrivée à Nyakakoma et présentation de civilité auprès des autorités de la place | D19: Parc National des Virunga | E19: Réunion | F19: Respect et salutation | G19: 45979 | H19: Moins d' 1h | I19: Centre | J19: Nyakakoma | K19: 8 | L19: 2 | M19: 0 | N19: Contact respectueux établi et coopération renforcée avec les autorités | O19: https://drive.google.com/open?id=1-a9ojtD5sKEJCclPiPLhLBJZJQ07JuV8 | P19: Joelle Isango, Jean Bosco BICHAMAKARA, Katya Emmanuel, John ingénieur , Five Grégoire, Five Martin | Q19: Reconnaissance et respect : Nous valorisons leur rôle et leur autorité dans la gestion de la pêcherie | R19: Accueil chaleureux des autorités et communication claire de notre arrivée dans la pêcherie | S19: Maintenir le respect des autorités, informer systématiquement de nos activités et renforcer la collaboration pour une gestion harmonieuse de la pêcherie.
A20: 45983.638 | B20: jisango@virunga.org | C20: Réunions préparatifs avec les autorités de la pêcherie, le Directeur de la pêcherie…. | D20: Parc National des Virunga | E20: Réunion | F20: Renforcer notre coordination pour une gestion responsable et harmonieuse de la pêcherie à Nyakakoma et préparer ensemble la journée de l’activité du 20 Novembre 2025 | G20: 45980 | H20: 2 h - 3 h | I20: Centre | J20: Nyakakoma | K20: 8 | L20: 2 | M20: 0 | N20: Une vision commune a été établie entre la pêcherie et le Parc | O20: https://drive.google.com/open?id=1lr4YdJwyEbWl4sbxknfrh_ZVxrm_Nui2 | P20: Five Grégoire, Five Martin, Jean Bosco Bichamakara , Joelle Isango, Katya Katondolo, Olivier Mukisya et John ingénieur | Q20: Renforcer la collaboration avec les autorités, garantir une preparation efficace | R20: Collaboration renforcée | S20: Respecter les autorités et maintenir une communication claire
A21: 45986.227 | B21: jisango@virunga.org | C21: Séance éducative avec les femmes de la pêcherie de Nyakakoma | D21: Parc National des Virunga | E21: Sensibilisation | F21: Une séance d’écoute avec les femmes de Nyakakoma pour valoriser leur rôle dans la conservation communautaire. | G21: 45985 | H21: 1 h - 2 h | I21: Centre | J21: Nyakakoma | K21: 0 | L21: 106 | M21: 0 | N21: Meilleur compréhension du rôle de la femme , engagement renforcé et identification de leur priorité pour la conservation | O21: https://drive.google.com/open?id=1WER361cS8JvsEgJebMoDucHzeT_uPGmp | P21: Five Grégoire, Five Martin , Joelle Isango , Olivier Mukisya, Jean bosco Bichamakara, Katya Katondolo | Q21: Renforcer l’implication des femmes dans la conservation communautaire à travers l’écoute , le dialoguer et leur participation active | R21: La forte participation des femmes qui ont exprimé avec clarté leur preoccupation et leur volonté de s’impliquer davantage dans la conservation | S21: Renforcer l’accompagnement des femmes de Nyakakoma par des séances régulières des dialogues d’écoute… afin de soutenir leurs participations active et durable dans la conservation communautaire

Sheet Dashboard_Auto
A1: DASHBOARD ACTIVITÉS - PARC NATIONAL DES VIRUNGA
A2: Système de Suivi des Activités - Relations Extérieures
A3: INDICATEURS CLÉS DE PERFORMANCE (KPI)
A4: KPI | B4: Valeur | C4: KPI | D4: Valeur | E4: KPI | F4: Valeur | G4: KPI | H4: Valeur
A5: Total Activités | B5: =COUNTA(Donnees_Activites!C2:C1000) -> 20 | C5: Total Participants | D5: =SUM(Donnees_Activites!K2:K1000)+SUM(Donnees_Activites!L2:L1000)+SUM(Donnees_Activites!M2:M1000) -> 3306 | E5: Moy. Participants/Act. | F5: =IF(B5>0, D5/B5, 0) -> 165.3 | G5: Activités Ce Mois | H5: =COUNTIFS(Donnees_Activites!G2:G1000, ">="&EOMONTH(TODAY(),-1)+1, Donnees_Activites!G2:G1000, "<="&EOMONTH(TODAY(),0)) -> 9
A6: Organisateurs Uniques | B6: =IFERROR(__xludf.DUMMYFUNCTION("COUNTA(UNIQUE(FILTER(Donnees_Activites!D2:D1000, Donnees_Activites!D2:D1000<>"""")))"),6) -> 6 | C6: Lieux Couverts | D6: =IFERROR(__xludf.DUMMYFUNCTION("COUNTA(UNIQUE(FILTER(Donnees_Activites!J2:J1000, Donnees_Activites!J2:J1000<>"""")))"),14) -> 14 | E6: Types d'Activités | F6: =IFERROR(__xludf.DUMMYFUNCTION("COUNTA(UNIQUE(FILTER(Donnees_Activites!E2:E1000, Donnees_Activites!E2:E1000<>"""")))"),11) -> 11 | G6: Secteurs Actifs | H6: =IFERROR(__xludf.DUMMYFUNCTION("COUNTA(UNIQUE(FILTER(Donnees_Activites!I2:I1000, Donnees_Activites!I2:I1000<>"""")))"),3) -> 3
A8: FILTRES INTERACTIFS
A9: Organisateur: | B9: Tous | C9: Type d'activité: | D9: Tous | E9: Secteur: | F9: Tous | G9: Période: | H9: Tous
A10: Utilisez les listes déroulantes pour filtrer les données. Sélectionnez "Tous" pour afficher toutes les données.
A12: TOP 10 ORGANISATEURS | F12: RÉPARTITION PAR TYPE D'ACTIVITÉ
A13: Organisateur | B13: Activités | C13: Participants | D13: Moy./Act. | F13: Type | G13: Activités | H13: Participants | I13: %
A14: =IFERROR(__xludf.DUMMYFUNCTION("QUERY({Donnees_Activites!D2:D1000, Donnees_Activites!K2:K1000+Donnees_Activites!L2:L1000+Donnees_Activites!M2:M1000}, ""SELECT Col1, COUNT(Col1), SUM(Col2) WHERE Col1 IS NOT NULL GROUP BY Col1 ORDER BY COUNT(Col1) DESC LIMIT 10 LABEL Col1 'Organisateur', "&"COUNT(Col1) 'Activités', SUM(Col2) 'Participants'"")"),"#REF!") -> #REF! | D14: {=IF(B14:B23>0, C14:C23/B14:B23, "")} | F14: =IFERROR(__xludf.DUMMYFUNCTION("QUERY({Donnees_Activites!E2:E1000, Donnees_Activites!K2:K1000+Donnees_Activites!L2:L1000+Donnees_Activites!M2:M1000}, ""SELECT Col1, COUNT(Col1), SUM(Col2), COUNT(Col1)/Donnees_Activites!B5 WHERE Col1 IS NOT NULL GROUP BY Col1 ORDER BY COUNT(Col1) DESC LA"&"BEL Col1 'Type', COUNT(Col1) 'Activités', SUM(Col2) 'Participants'"")"),"#REF!") -> #REF!
A25: TOP 10 LIEUX LES PLUS FRÉQUENTÉS | F25: ÉVOLUTION MENSUELLE (6 DERNIERS MOIS)
A26: Lieu | B26: Secteur | C26: Activités | D26: Participants | F26: Mois | G26: Activités | H26: Participants | I26: Moy./Act.
A27: =IFERROR(__xludf.DUMMYFUNCTION("QUERY({Donnees_Activites!J2:J1000, Donnees_Activites!I2:I1000, Donnees_Activites!K2:K1000+Donnees_Activites!L2:L1000+Donnees_Activites!M2:M1000}, ""SELECT Col1, Col2, COUNT(Col1), SUM(Col3) WHERE Col1 IS NOT NULL GROUP BY Col1, Col2 ORDER BY COUNT(Col1) D"&"ESC LIMIT 10 LABEL Col1 'Lieu', Col2 'Secteur', COUNT(Col1) 'Activités', SUM(Col3) 'Participants'"")"),"#REF!") -> #REF! | F27: =TEXT(EDATE(TODAY(), -5), "mmm yyyy") -> juin yyyy | G27: =COUNTIFS(Donnees_Activites!G2:G1000, ">="&DATE(YEAR(EDATE(TODAY(), -5)), MONTH(EDATE(TODAY(), -5)), 1), Donnees_Activites!G2:G1000, "<"&DATE(YEAR(EDATE(TODAY(), -4)), MONTH(EDATE(TODAY(), -4)), 1)) -> 0 | H27: #N/A | I27: =IF(G27>0, H27/G27, 0) -> 0
F28: =TEXT(EDATE(TODAY(), -4), "mmm yyyy") -> juil yyyy | G28: =COUNTIFS(Donnees_Activites!G2:G1000, ">="&DATE(YEAR(EDATE(TODAY(), -4)), MONTH(EDATE(TODAY(), -4)), 1), Donnees_Activites!G2:G1000, "<"&DATE(YEAR(EDATE(TODAY(), -3)), MONTH(EDATE(TODAY(), -3)), 1)) -> 0 | H28: #N/A | I28: =IF(G28>0, H28/G28, 0) -> 0
F29: =TEXT(EDATE(TODAY(), -3), "mmm yyyy") -> août yyyy | G29: =COUNTIFS(Donnees_Activites!G2:G1000, ">="&DATE(YEAR(EDATE(TODAY(), -3)), MONTH(EDATE(TODAY(), -3)), 1), Donnees_Activites!G2:G1000, "<"&DATE(YEAR(EDATE(TODAY(), -2)), MONTH(EDATE(TODAY(), -2)), 1)) -> 0 | H29: #N/A | I29: =IF(G29>0, H29/G29, 0) -> 0
F30: =TEXT(EDATE(TODAY(), -2), "mmm yyyy") -> sept yyyy | G30: =COUNTIFS(Donnees_Activites!G2:G1000, ">="&DATE(YEAR(EDATE(TODAY(), -2)), MONTH(EDATE(TODAY(), -2)), 1), Donnees_Activites!G2:G1000, "<"&DATE(YEAR(EDATE(TODAY(), -1)), MONTH(EDATE(TODAY(), -1)), 1)) -> 0 | H30: #N/A | I30: =IF(G30>0, H30/G30, 0) -> 0
F31: =TEXT(EDATE(TODAY(), -1), "mmm yyyy") -> oct yyyy | G31: =COUNTIFS(Donnees_Activites!G2:G1000, ">="&DATE(YEAR(EDATE(TODAY(), -1)), MONTH(EDATE(TODAY(), -1)), 1), Donnees_Activites!G2:G1000, "<"&DATE(YEAR(EDATE(TODAY(), 0)), MONTH(EDATE(TODAY(), 0)), 1)) -> 11 | H31: #N/A | I31: =IF(G31>0, H31/G31, 0) -> #VALUE!
F32: =TEXT(EDATE(TODAY(), 0), "mmm yyyy") -> nov yyyy | G32: =COUNTIFS(Donnees_Activites!G2:G1000, ">="&DATE(YEAR(EDATE(TODAY(), 0)), MONTH(EDATE(TODAY(), 0)), 1), Donnees_Activites!G2:G1000, "<"&DATE(YEAR(EDATE(TODAY(), --1)), MONTH(EDATE(TODAY(), --1)), 1)) -> 9 | H32: #N/A | I32: =IF(G32>0, H32/G32, 0) -> #VALUE!
A34: PERFORMANCE PAR SECTEUR
A35: Secteur | B35: Activités | C35: Participants | D35: Moy./Act. | E35: Lieux | F35: Types Act. | G35: Organisateurs | H35: Part %
A36: =IFERROR(__xludf.DUMMYFUNCTION("QUERY({Donnees_Activites!I2:I1000, Donnees_Activites!K2:K1000+Donnees_Activites!L2:L1000+Donnees_Activites!M2:M1000}, ""SELECT Col1, COUNT(Col1), SUM(Col2), SUM(Col2)/COUNT(Col1) WHERE Col1 IS NOT NULL GROUP BY Col1 ORDER BY COUNT(Col1) DESC LABEL Col1 'S"&"ecteur', COUNT(Col1) 'Activités', SUM(Col2) 'Participants', SUM(Col2)/COUNT(Col1) 'Moy./Act.'"")"),"#REF!") -> #REF! | E36: =IFERROR(__xludf.DUMMYFUNCTION("ARRAYFORMULA(IF(A36:A1000<>"""", COUNTUNIQUEIFS(Donnees_Activites!J2:J1000, Donnees_Activites!I2:I1000, A36:A1000), """"))"),"#REF!") -> #REF! | F36: =IFERROR(__xludf.DUMMYFUNCTION("ARRAYFORMULA(IF(A36:A1000<>"""", COUNTUNIQUEIFS(Donnees_Activites!E2:E1000, Donnees_Activites!I2:I1000, A36:A1000), """"))"),"#REF!") -> #REF! | G36: =IFERROR(__xludf.DUMMYFUNCTION("ARRAYFORMULA(IF(A36:A1000<>"""", COUNTUNIQUEIFS(Donnees_Activites!D2:D1000, Donnees_Activites!I2:I1000, A36:A1000), """"))"),"#REF!") -> #REF! | H36: {=IF(B36:B1000<>"", B36:B1000/SUM(B36:B1000), "")}
E37: =IFERROR(__xludf.DUMMYFUNCTION("""COMPUTED_VALUE"""),"") | F37: =IFERROR(__xludf.DUMMYFUNCTION("""COMPUTED_VALUE"""),"") | G37: =IFERROR(__xludf.DUMMYFUNCTION("""COMPUTED_VALUE"""),"")
E38: =IFERROR(__xludf.DUMMYFUNCTION("""COMPUTED_VALUE"""),"") | F38: =IFERROR(__xludf.DUMMYFUNCTION("""COMPUTED_VALUE"""),"") | G38: =IFERROR(__xludf.DUMMYFUNCTION("""COMPUTED_VALUE"""),"")
E39: =IFERROR(__xludf.DUMMYFUNCTION("""COMPUTED_VALUE"""),"") | F39: =IFERROR(__xludf.DUMMYFUNCTION("""COMPUTED_VALUE"""),"") | G39: =IFERROR(__xludf.DUMMYFUNCTION("""COMPUTED_VALUE"""),"")
E40: =IFERROR(__xludf.DUMMYFUNCTION("""COMPUTED_VALUE"""),"") | F40: =IFERROR(__xludf.DUMMYFUNCTION("""COMPUTED_VALUE"""),"") | G40: =IFERROR(__xludf.DUMMYFUNCTION("""COMPUTED_VALUE"""),"")
E41: =IFERROR(__xludf.DUMMYFUNCTION("""COMPUTED_VALUE"""),"") | F41: =IFERROR(__xludf.DUMMYFUNCTION("""COMPUTED_VALUE"""),"") | G41: =IFERROR(__xludf.DUMMYFUNCTION("""COMPUTED_VALUE"""),"")
E42: =IFERROR(__xludf.DUMMYFUNCTION("""COMPUTED_VALUE"""),"") | F42: =IFERROR(__xludf.DUMMYFUNCTION("""COMPUTED_VALUE"""),"") | G42: =IFERROR(__xludf.DUMMYFUNCTION("""COMPUTED_VALUE"""),"")
E43: =IFERROR(__xludf.DUMMYFUNCTION("""COMPUTED_VALUE"""),"") | F43: =IFERROR(__xludf.DUMMYFUNCTION("""COMPUTED_VALUE"""),"") | G43: =IFERROR(__xludf.DUMMYFUNCTION("""COMPUTED_VALUE"""),"")
E44: =IFERROR(__xludf.DUMMYFUNCTION("""COMPUTED_VALUE"""),"") | F44: =IFERROR(__xludf.DUMMYFUNCTION("""COMPUTED_VALUE"""),"") | G44: =IFERROR(__xludf.DUMMYFUNCTION("""COMPUTED_VALUE"""),"")
A45: Dernière mise à jour: 10/11/2025 à 23:48:12
E46: =IFERROR(__xludf.DUMMYFUNCTION("""COMPUTED_VALUE"""),"") | F46: =IFERROR(__xludf.DUMMYFUNCTION("""COMPUTED_VALUE"""),"") | G46: =IFERROR(__xludf.DUMMYFUNCTION("""COMPUTED_VALUE"""),"")
E47: =IFERROR(__xludf.DUMMYFUNCTION("""COMPUTED_VALUE"""),"") | F47: =IFERROR(__xludf.DUMMYFUNCTION("""COMPUTED_VALUE"""),"") | G47: =IFERROR(__xludf.DUMMYFUNCTION("""COMPUTED_VALUE"""),"")
E48: =IFERROR(__xludf.DUMMYFUNCTION("""COMPUTED_VALUE"""),"") | F48: =IFERROR(__xludf.DUMMYFUNCTION("""COMPUTED_VALUE"""),"") | G48: =IFERROR(__xludf.DUMMYFUNCTION("""COMPUTED_VALUE"""),"")
E49: =IFERROR(__xludf.DUMMYFUNCTION("""COMPUTED_VALUE"""),"") | F49: =IFERROR(__xludf.DUMMYFUNCTION("""COMPUTED_VALUE"""),"") | G49: =IFERROR(__xludf.DUMMYFUNCTION("""COMPUTED_VALUE"""),"")
E50: =IFERROR(__xludf.DUMMYFUNCTION("""COMPUTED_VALUE"""),"") | F50: =IFERROR(__xludf.DUMMYFUNCTION("""COMPUTED_VALUE"""),"") | G50: =IFERROR(__xludf.DUMMYFUNCTION("""COMPUTED_VALUE"""),"")
E51: =IFERROR(__xludf.DUMMYFUNCTION("""COMPUTED_VALUE"""),"") | F51: =IFERROR(__xludf.DUMMYFUNCTION("""COMPUTED_VALUE"""),"") | G51: =IFERROR(__xludf.DUMMYFUNCTION("""COMPUTED_VALUE"""),"")
E52: =IFERROR(__xludf.DUMMYFUNCTION("""COMPUTED_VALUE"""),"") | F52: =IFERROR(__xludf.DUMMYFUNCTION("""COMPUTED_VALUE"""),"") | G52: =IFERROR(__xludf.DUMMYFUNCTION("""COMPUTED_VALUE"""),"")
E53: =IFERROR(__xludf.DUMMYFUNCTION("""COMPUTED_VALUE"""),"") | F53: =IFERROR(__xludf.DUMMYFUNCTION("""COMPUTED_VALUE"""),"") | G53: =IFERROR(__xludf.DUMMYFUNCTION("""COMPUTED_VALUE"""),"")
...

Sheet Historique
A1: Mois | B1: Nombre Activites | C1: Total Participants | D1: Date Archive
